<?xml version="1.0" encoding="utf-8"?>
<robot
  name="littlewhite">
  <mujoco>
    <compiler
      meshdir="../meshes"
      balanceinertia="true"
      discardvisual="false" />
  </mujoco>
  <link
    name="base_link">
    <inertial>
      <origin
        xyz="-0.01204342 -0.00011397 -0.00061410"
        rpy="0 0 0" />
      <mass
        value="2.0" />
      <inertia 
        ixx="0.00509927" 
        iyy="0.01393531" 
        izz="0.01818843" 
        ixy="0.00000168" 
        iyz="0.00000252" 
        ixz="-0.00002258"/>
    </inertial>
    <visual>
      <origin
        xyz="0 0 0"
        rpy="0 0 0" />
      <geometry>
        <mesh
          filename="../meshes/base_link.STL" />
      </geometry>
      <material
        name="">
        <color
          rgba="0.792156862745098 0.819607843137255 0.933333333333333 1" />
      </material>
    </visual>
    <collision>
      <origin
        xyz="0 0 0"
        rpy="0 0 0" />
      <geometry>
        <mesh
          filename="../meshes/base_link_collision.stl" />
      </geometry>
    </collision>
  </link>
  <link
    name="FL_hip_link">
    <inertial>
      <origin
        xyz="0.03331333 0.00218418 -0.00003895"
        rpy="0 0 0" />
      <mass
        value="0.3" />
      <inertia 
        ixx="0.00026341" 
        iyy="0.00017811" 
        izz="0.00028488" 
        ixy="-0.00000101" 
        iyz="0.0000011" 
        ixz="-0.00000025"/>
    </inertial>
    <visual>
      <origin
        xyz="0 0 0"
        rpy="0 0 0" />
      <geometry>
        <mesh
          filename="../meshes/FL_hip_link.STL" />
      </geometry>
      <material
        name="">
        <color
          rgba="0.792156862745098 0.819607843137255 0.933333333333333 1" />
      </material>
    </visual>
    <collision>
      <origin
        xyz="0 0 0"
        rpy="0 0 0" />
      <geometry>
        <mesh
          filename="../meshes/FL_hip_collision.stl" />
      </geometry>
    </collision>
  </link>
  <joint
    name="FL_hip_joint"
    type="revolute">
    <origin
      xyz="0.1234 0.0510661438491521 0"
      rpy="0 0 0" />
    <parent
      link="base_link" />
    <child
      link="FL_hip_link" />
    <axis
      xyz="1 0 0" />
    <limit
      lower="-1.0472"
      upper="1.0472"
      effort="23.7"
      velocity="30.1" />
  </joint>
  <link
    name="FL_thigh_link">
    <inertial>
      <origin
        xyz="-0.04948796 0.00014953 -0.08497632"
        rpy="0 0 0" />
      <mass
        value="0.48" />
      <inertia 
        ixx="0.00169763" 
        iyy="0.00215821" 
        izz="0.00052878" 
        ixy="-0.00001723" 
        iyz="-0.00003114" 
        ixz="-0.00075516"/>
    </inertial>
    <visual>
      <origin
        xyz="0 0 0"
        rpy="0 0 0" />
      <geometry>
        <mesh
          filename="../meshes/FL_thigh_link.STL" />
      </geometry>
      <material
        name="">
        <color
          rgba="0.792156862745098 0.819607843137255 0.933333333333333 1" />
      </material>
    </visual>
    <collision>
      <origin
        xyz="0 0 0"
        rpy="0 0 0" />
      <geometry>
        <mesh
          filename="../meshes/FL_thigh_collision.stl" />
      </geometry>
    </collision>
  </link>
  <joint
    name="FL_thigh_joint"
    type="revolute">
    <origin
      xyz="0.0364999999998923 0.0595338561508431 0"
      rpy="0 0 0" />
    <parent
      link="FL_hip_link" />
    <child
      link="FL_thigh_link" />
    <axis
      xyz="0 1 0" />
    <limit
      lower="-1.5708"
      upper="1.5708"
      effort="23.7"
      velocity="30.1" />
  </joint>
  <link
    name="FL_calf_link">
    <inertial>
      <origin
        xyz="0.04216262 -0.00381767 -0.06204980"
        rpy="0 0 0" />
      <mass
        value="0.04" />
      <inertia 
        ixx="0.00007524" 
        iyy="0.00010881" 
        izz="0.00003626" 
        ixy="0.00000117" 
        iyz="-0.00000175" 
        ixz="0.0000485"/>
    </inertial>
    <visual>
      <origin
        xyz="0 0 0"
        rpy="0 0 0" />
      <geometry>
        <mesh
          filename="../meshes/FL_calf_link.STL" />
      </geometry>
      <material
        name="">
        <color
          rgba="0.792156862745098 0.819607843137255 0.933333333333333 1" />
      </material>
    </visual>
    <collision>
      <origin
        xyz="0 0 0"
        rpy="0 0 0" />
      <geometry>
        <mesh
          filename="../meshes/FL_calf_collision.stl" />
      </geometry>
    </collision>
  </link>
  <joint
    name="FL_calf_joint"
    type="revolute">
    <origin
      xyz="-0.0797979547511169 0.0057100000074559 -0.177734859753232"
      rpy="0 0 0" />
    <parent
      link="FL_thigh_link" />
    <child
      link="FL_calf_link" />
    <axis
      xyz="0 1 0" />
    <limit
      lower="-1.91"
      upper="0.0"
      effort="45.43"
      velocity="15.70" />
  </joint>
  <link
    name="FL_foot_link">
    <inertial>
      <origin
        xyz="0.00000526 0.00079999 -0.02548986"
        rpy="0 0 0" />
      <mass
        value="0.01000000" />
      <inertia
        ixx="0.00000939"
        ixy="0.00000000"
        ixz="0.00000000"
        iyy="0.00000881"
        iyz="-0.00000007"
        izz="0.00000129" />
    </inertial>
    <visual>
      <origin
        xyz="0 0 0"
        rpy="0 0 0" />
      <geometry>
        <mesh
          filename="../meshes/FL_paw_link.STL" />
      </geometry>
      <material
        name="">
        <color
          rgba="0.792156862745098 0.819607843137255 0.933333333333333 1" />
      </material>
    </visual>
    <collision>
      <origin
        xyz="0 0 0"
        rpy="0 0 0" />
      <geometry>
        <mesh
          filename="../meshes/FL_paw_collision.stl" />
      </geometry>
    </collision>
  </link>
  <joint
    name="FL_foot_joint"
    type="fixed">
    <origin
      xyz="0.0808648551671098 -0.00455000000710462 -0.13556178756198"
      rpy="0 0 -1.57079389681705" />
    <parent
      link="FL_calf_link" />
    <child
      link="FL_foot_link" />
    <axis
      xyz="0 0 0" />
  </joint>
  <link
    name="FR_hip_link">
    <inertial>
      <origin
        xyz="0.02763628 0.00800779 -0.00000706"
        rpy="0 0 0" />
      <mass
        value="0.3" />
      <inertia 
        ixx="0.00019088" 
        iyy="0.0002331" 
        izz="0.00024199" 
        ixy="-0.00002362" 
        iyz="-0.00000024" 
        ixz="-0.00000003"/>
    </inertial>
    <visual>
      <origin
        xyz="0 0 0"
        rpy="0 0 0" />
      <geometry>
        <mesh
          filename="../meshes/FR_hip_link.STL" />
      </geometry>
      <material
        name="">
        <color
          rgba="0.792156862745098 0.819607843137255 0.933333333333333 1" />
      </material>
    </visual>
    <collision>
      <origin
        xyz="0 0 0"
        rpy="0 0 0" />
      <geometry>
        <mesh
          filename="../meshes/FR_hip_collision.stl" />
      </geometry>
    </collision>
  </link>
  <joint
    name="FR_hip_joint"
    type="revolute">
    <origin
      xyz="0.1234 -0.0509338542435013 0"
      rpy="0 0 0" />
    <parent
      link="base_link" />
    <child
      link="FR_hip_link" />
    <axis
      xyz="1 0 0" />
    <limit
      lower="-1.0472"
      upper="1.0472"
      effort="23.7"
      velocity="30.1" />
  </joint>
  <link
    name="FR_thigh_link">
    <inertial>
      <origin
        xyz="-0.04948940 -0.00014939 -0.08497556"
        rpy="0 0 0" />
      <mass
        value="0.48" />
      <inertia 
        ixx="0.00169762" 
        iyy="0.0021581" 
        izz="0.00052868" 
        ixy="0.00001724" 
        iyz="0.00003113" 
        ixz="-0.00075512"/>
    </inertial>
    <visual>
      <origin
        xyz="0 0 0"
        rpy="0 0 0" />
      <geometry>
        <mesh
          filename="../meshes/FR_thigh_link.STL" />
      </geometry>
      <material
        name="">
        <color
          rgba="0.792156862745098 0.819607843137255 0.933333333333333 1" />
      </material>
    </visual>
    <collision>
      <origin
        xyz="0 0 0"
        rpy="0 0 0" />
      <geometry>
        <mesh
          filename="../meshes/FR_thigh_collision.stl" />
      </geometry>
    </collision>
  </link>
  <joint
    name="FR_thigh_joint"
    type="revolute">
    <origin
      xyz="0.0364999999998896 -0.0596661457564947 0"
      rpy="0 0 0" />
    <parent
      link="FR_hip_link" />
    <child
      link="FR_thigh_link" />
    <axis
      xyz="0 1 0" />
    <limit
      lower="-1.5708"
      upper="1.5708"
      effort="23.7"
      velocity="30.1" />
  </joint>
  <link
    name="FR_calf_link">
    <inertial>
      <origin
        xyz="0.04216523 0.00382068 -0.06204916"
        rpy="0 0 0" />
      <mass
        value="0.04" />
      <inertia 
        ixx="0.00007524" 
        iyy="0.00010881" 
        izz="0.00003627" 
        ixy="-0.00000117" 
        iyz="0.00000176" 
        ixz="0.00004851"/>
    </inertial>
    <visual>
      <origin
        xyz="0 0 0"
        rpy="0 0 0" />
      <geometry>
        <mesh
          filename="../meshes/FR_calf_link.STL" />
      </geometry>
      <material
        name="">
        <color
          rgba="0.792156862745098 0.819607843137255 0.933333333333333 1" />
      </material>
    </visual>
    <collision>
      <origin
        xyz="0 0 0"
        rpy="0 0 0" />
      <geometry>
        <mesh
          filename="../meshes/FR_calf_collision.stl" />
      </geometry>
    </collision>
  </link>
  <joint
    name="FR_calf_joint"
    type="revolute">
    <origin
      xyz="-0.07979795475272 -0.00571000000745676 -0.177734859752691"
      rpy="0 0 0" />
    <parent
      link="FR_thigh_link" />
    <child
      link="FR_calf_link" />
    <axis
      xyz="0 1 0" />
    <limit
      lower="-1.91"
      upper="0.0"
      effort="45.43"
      velocity="15.70" />
  </joint>
  <link
    name="FR_foot_link">
    <inertial>
        <origin
          xyz="0.00078591 0.00000000 -0.02549509"
          rpy="0 0 0" />
        <mass
          value="0.01000000" />
        <inertia
          ixx="0.00000881"
          ixy="0.00000000"
          ixz="-0.00000007"
          iyy="0.00000939"
          iyz="0.00000000"
          izz="0.00000129" />
      </inertial>
    <visual>
      <origin
        xyz="0 0 0"
        rpy="0 0 0" />
      <geometry>
        <mesh
          filename="../meshes/FR_paw_link.STL" />
      </geometry>
      <material
        name="">
        <color
          rgba="0.792156862745098 0.819607843137255 0.933333333333333 1" />
      </material>
    </visual>
    <collision>
      <origin
        xyz="0 0 0"
        rpy="0 0 0" />
      <geometry>
        <mesh
          filename="../meshes/FL_paw_collision.stl" />
      </geometry>
    </collision>
  </link>
  <joint
    name="FR_foot_joint"
    type="fixed">
    <origin
      xyz="0.0808736911194098 0.00455000000745538 -0.135559326977152"
      rpy="0 0 0" />
    <parent
      link="FR_calf_link" />
    <child
      link="FR_foot_link" />
    <axis
      xyz="0 0 0" />
  </joint>
  <link
    name="RL_hip_link">
    <inertial>
      <origin
        xyz="-0.03348869 0.00218418 -0.00018813"
        rpy="0 0 0" />
      <mass
        value="0.3" />
      <inertia 
        ixx="0.00026341" 
        iyy="0.00017842" 
        izz="0.00028519" 
        ixy="0.0000014" 
        iyz="-0.00000075" 
        ixz="-0.00000036"/>
    </inertial>
    <visual>
      <origin
        xyz="0 0 0"
        rpy="0 0 0" />
      <geometry>
        <mesh
          filename="../meshes/RL_hip_link.STL" />
      </geometry>
      <material
        name="">
        <color
          rgba="0.792156862745098 0.819607843137255 0.933333333333333 1" />
      </material>
    </visual>
    <collision>
      <origin
        xyz="0 0 0"
        rpy="0 0 0" />
      <geometry>
        <mesh
          filename="../meshes/RL_hip_collision.stl" />
      </geometry>
    </collision>
  </link>
  <joint
    name="RL_hip_joint"
    type="revolute">
    <origin
      xyz="-0.1234 0.0510661438491522 0"
      rpy="0 0 0" />
    <parent
      link="base_link" />
    <child
      link="RL_hip_link" />
    <axis
      xyz="1 0 0" />
    <limit
      lower="-1.0472"
      upper="1.0472"
      effort="23.7"
      velocity="30.1" />
  </joint>
  <link
    name="RL_thigh_link">
    <inertial>
      <origin
        xyz="-0.05192485 0.00014953 -0.08350948"
        rpy="0 0 0" />
      <mass
        value="0.48" />
      <inertia 
        ixx="0.00165299" 
        iyy="0.00215822" 
        izz="0.00057342" 
        ixy="-0.00001812" 
        iyz="-0.00003062" 
        ixz="-0.00078769"/>
    </inertial>
    <visual>
      <origin
        xyz="0 0 0"
        rpy="0 0 0" />
      <geometry>
        <mesh
          filename="../meshes/RL_thigh_link.STL" />
      </geometry>
      <material
        name="">
        <color
          rgba="0.792156862745098 0.819607843137255 0.933333333333333 1" />
      </material>
    </visual>
    <collision>
      <origin
        xyz="0 0 0"
        rpy="0 0 0" />
      <geometry>
        <mesh
          filename="../meshes/FL_thigh_collision.stl" />
      </geometry>
    </collision>
  </link>
  <joint
    name="RL_thigh_joint"
    type="revolute">
    <origin
      xyz="-0.0364999999998925 0.059533856150843 0"
      rpy="0 0 0" />
    <parent
      link="RL_hip_link" />
    <child
      link="RL_thigh_link" />
    <axis
      xyz="0 1 0" />
    <limit
      lower="-1.5708"
      upper="1.5708"
      effort="23.7"
      velocity="30.1" />
  </joint>
  <link
    name="RL_calf_link">
    <inertial>
      <origin
        xyz="0.03963025 -0.00382049 -0.06348497"
        rpy="0 0 0" />
      <mass
        value="0.04" />
      <inertia 
        ixx="0.00007859" 
        iyy="0.00010881" 
        izz="0.00003292" 
        ixy="0.00000111" 
        iyz="-0.0000018" 
        ixz="0.00004703"/>
    </inertial>
    <visual>
      <origin
        xyz="0 0 0"
        rpy="0 0 0" />
      <geometry>
        <mesh
          filename="../meshes/RL_calf_link.STL" />
      </geometry>
      <material
        name="">
        <color
          rgba="0.792156862745098 0.819607843137255 0.933333333333333 1" />
      </material>
    </visual>
    <collision>
      <origin
        xyz="0 0 0"
        rpy="0 0 0" />
      <geometry>
        <mesh
          filename="../meshes/FL_calf_collision.stl" />
      </geometry>
    </collision>
  </link>
  <joint
    name="RL_calf_joint"
    type="revolute">
    <origin
      xyz="-0.0845699035706932 0.00571000000745585 -0.175355557164464"
      rpy="0 0 0" />
    <parent
      link="RL_thigh_link" />
    <child
      link="RL_calf_link" />
    <axis
      xyz="0 1 0" />
    <limit
      lower="-1.91"
      upper="0.0"
      effort="45.43"
      velocity="15.70" />
  </joint>
  <link
    name="RL_foot_link">
    <inertial>
      <origin
        xyz="-0.00010845 0.00000000 -0.02550655"
        rpy="0 0 0" />
      <mass
        value="0.01000000" />
      <inertia
        ixx="0.00000881"
        ixy="0.00000000"
        ixz="0.00000020"
        iyy="0.00000939"
        iyz="0.00000000"
        izz="0.00000129" />
    </inertial>
    <visual>
      <origin
        xyz="0 0 0"
        rpy="0 0 0" />
      <geometry>
        <mesh
          filename="../meshes/RL_paw_link.STL" />
      </geometry>
      <material
        name="">
        <color
          rgba="0.792156862745098 0.819607843137255 0.933333333333333 1" />
      </material>
    </visual>
    <collision>
      <origin
        xyz="0 0 0"
        rpy="0 0 0" />
      <geometry>
        <mesh
          filename="../meshes/FL_paw_collision.stl" />
      </geometry>
    </collision>
  </link>
  <joint
    name="RL_foot_joint"
    type="fixed">
    <origin
      xyz="0.0757392521105553 -0.00455000000746522 -0.138306710543388"
      rpy="0 0 0" />
    <parent
      link="RL_calf_link" />
    <child
      link="RL_foot_link" />
    <axis
      xyz="0.94688 0 -0.32158" />
  </joint>
  <link
    name="RR_hip_link">
    <inertial>
      <origin
        xyz="-0.02767159 0.00800779 -0.00003868"
        rpy="0 0 0" />
      <mass
        value="0.3" />
      <inertia 
        ixx="0.00019089" 
        iyy="0.00023328" 
        izz="0.00024218" 
        ixy="0.00002343" 
        iyz="0.00000004" 
        ixz="-0.00000014"/>
    </inertial>
    <visual>
      <origin
        xyz="0 0 0"
        rpy="0 0 0" />
      <geometry>
        <mesh
          filename="../meshes/RR_hip_link.STL" />
      </geometry>
      <material
        name="">
        <color
          rgba="0.792156862745098 0.819607843137255 0.933333333333333 1" />
      </material>
    </visual>
    <collision>
      <origin
        xyz="0 0 0"
        rpy="0 0 0" />
      <geometry>
        <mesh
          filename="../meshes/RR_hip_collision.stl" />
      </geometry>
    </collision>
  </link>
  <joint
    name="RR_hip_joint"
    type="revolute">
    <origin
      xyz="-0.1234 -0.0509338542435013 0"
      rpy="0 0 0" />
    <parent
      link="base_link" />
    <child
      link="RR_hip_link" />
    <axis
      xyz="1 0 0" />
    <limit
      lower="-1.0472"
      upper="1.0472"
      effort="23.7"
      velocity="30.1" />
  </joint>
  <link
    name="RR_thigh_link">
    <inertial>
      <origin
        xyz="-0.05192615 -0.00014945 -0.08350805"
        rpy="0 0 0" />
      <mass
        value="0.48" />
      <inertia 
        ixx="0.00165301" 
        iyy="0.00215813" 
        izz="0.00057332" 
        ixy="0.00001813" 
        iyz="0.0000306" 
        ixz="-0.00078767"/>
    </inertial>
    <visual>
      <origin
        xyz="0 0 0"
        rpy="0 0 0" />
      <geometry>
        <mesh
          filename="../meshes/RR_thigh_link.STL" />
      </geometry>
      <material
        name="">
        <color
          rgba="0.792156862745098 0.819607843137255 0.933333333333333 1" />
      </material>
    </visual>
    <collision>
      <origin
        xyz="0 0 0"
        rpy="0 0 0" />
      <geometry>
        <mesh
          filename="../meshes/FR_thigh_collision.stl" />
      </geometry>
    </collision>
  </link>
  <joint
    name="RR_thigh_joint"
    type="revolute">
    <origin
      xyz="-0.0364999999998896 -0.0596661457564947 0"
      rpy="0 0 0" />
    <parent
      link="RR_hip_link" />
    <child
      link="RR_thigh_link" />
    <axis
      xyz="0 1 0" />
    <limit
      lower="-1.5708"
      upper="1.5708"
      effort="23.7"
      velocity="30.1" />
  </joint>
  <link
    name="RR_calf_link">
    <inertial>
      <origin
        xyz="0.03996525 0.00382068 -0.06348829"
        rpy="0 0 0" />
      <mass
        value="0.04" />
      <inertia 
        ixx="0.00007859" 
        iyy="0.00010881" 
        izz="0.00003292" 
        ixy="-0.00000111" 
        iyz="0.0000018" 
        ixz="0.00004703"/>
    </inertial>
    <visual>
      <origin
        xyz="0 0 0"
        rpy="0 0 0" />
      <geometry>
        <mesh
          filename="../meshes/RR_calf_link.STL" />
      </geometry>
      <material
        name="">
        <color
          rgba="0.792156862745098 0.819607843137255 0.933333333333333 1" />
      </material>
    </visual>
    <collision>
      <origin
        xyz="0 0 0"
        rpy="0 0 0" />
      <geometry>
        <mesh
          filename="../meshes/FR_calf_collision.stl" />
      </geometry>
    </collision>
  </link>
  <joint
    name="RR_calf_joint"
    type="revolute">
    <origin
      xyz="-0.0849050519458896 -0.00571000000745676 -0.175352576565309"
      rpy="0 0 0" />
    <parent
      link="RR_thigh_link" />
    <child
      link="RR_calf_link" />
    <axis
      xyz="0 1 0" />
    <limit
      lower="-1.91"
      upper="0.0"
      effort="45.43"
      velocity="15.70" />
  </joint>
  <link
    name="RR_foot_link">
    <inertial>
      <origin
        xyz="-0.00010786 0.00000000 -0.02550697"
        rpy="0 0 0" />
      <mass
        value="0.01000000" />
      <inertia
        ixx="0.00000881"
        ixy="0.00000000"
        ixz="0.00000020"
        iyy="0.00000939"
        iyz="0.00000000"
        izz="0.00000129" />
    </inertial>
    <visual>
      <origin
        xyz="0 0 0"
        rpy="0 0 0" />
      <geometry>
        <mesh
          filename="../meshes/RR_paw_link.STL" />
      </geometry>
      <material
        name="">
        <color
          rgba="0.792156862745098 0.819607843137255 0.933333333333333 1" />
      </material>
    </visual>
    <collision>
      <origin
        xyz="0 0 0"
        rpy="0 0 0" />
      <geometry>
        <mesh
          filename="../meshes/FL_paw_collision.stl" />
      </geometry>
    </collision>
  </link>
  <joint
    name="RR_foot_joint"
    type="fixed">
    <origin
      xyz="0.0760744000854129 0.00455000000746143 -0.138309691263331"
      rpy="0 0 0" />
    <parent
      link="RR_calf_link" />
    <child
      link="RR_foot_link" />
    <axis
      xyz="0 0 0" />
  </joint>
</robot>
