<?xml version="1.0" ?>
<robot name="simple_little_white" xmlns:xacro="http://www.ros.org/wiki/xacro">
<mujoco>
  <compiler
    meshdir="../meshes"
    balanceinertia="true"
    discardvisual="false" />
</mujoco>
<link name="base_link">
  <inertial>
    <origin xyz="-0.058219409920514 -0.00015551013219091903 -0.0009354154163044696" rpy="0 0 0"/>
    <mass value="6.512426707346096"/>
    <inertia ixx="0.018427" iyy="0.057419" izz="0.07308" ixy="8e-06" iyz="3.3e-05" ixz="0.000146"/>
  </inertial>
  <visual>
    <origin xyz="0 0 0" rpy="0 0 0"/>
    <geometry>
      <mesh filename="package://simple_little_white_description/meshes/base_link.stl" scale="0.001 0.001 0.001"/>
    </geometry>
    <material name="silver"/>
  </visual>
  <collision>
    <origin xyz="-0.06 0 0" rpy="0 0 0"/>
    <geometry>
      <box size="0.255 0.165 0.06"/>
    </geometry>
  </collision>
</link>

<link name="FL_hip">
  <inertial>
    <origin xyz="0.0350899197978302 -0.01335927107083651 -4.816375521328421e-05" rpy="0 0 0"/>
    <mass value="1.1880376921996947"/>
    <inertia ixx="0.000534" iyy="0.000575" izz="0.000581" ixy="2.3e-05" iyz="-0.0" ixz="-0.0"/>
  </inertial>
  <visual>
    <origin xyz="-0.062848 -0.050963 0.001091" rpy="0 0 0"/>
    <geometry>
      <mesh filename="package://simple_little_white_description/meshes/fl_hip_1.stl" scale="0.001 0.001 0.001"/>
    </geometry>
    <material name="silver"/>
  </visual>
  <collision>
    <origin xyz="0.0365 -0.016 0" rpy="1.57 0 0"/>
    <geometry>
      <cylinder radius="0.031" length="0.055"/>
    </geometry>
  </collision>
</link>

<link name="FL_thigh">
  <inertial>
    <origin xyz="-0.0045084384857524 0.03041494357767835 -0.038282955304764055" rpy="0 0 0"/>
    <mass value="1.5258680170230223"/>
    <inertia ixx="0.006064" iyy="0.006141" izz="0.000707" ixy="8e-05" iyz="0.000589" ixz="-0.000489"/>
  </inertial>
  <visual>
    <origin xyz="-0.099348 -0.0655 0.001201" rpy="0 0 0"/>
    <geometry>
      <mesh filename="package://simple_little_white_description/meshes/fl_thigh_1.stl" scale="0.001 0.001 0.001"/>
    </geometry>
    <material name="silver"/>
  </visual>
  <collision>
    <origin xyz="0 0.03 0" rpy="1.57 0 0"/>
    <geometry>
      <cylinder radius="0.031" length="0.055"/>
    </geometry>
  </collision>
  <collision>
  <origin xyz="-0.025 0.045 -0.08" rpy="0 0 0"/>
  <geometry>
    <box size="0.02 0.03 0.15"/>
  </geometry>
</collision>
</link>

<link name="FL_calf">
  <inertial>
    <origin xyz="0.013545723984630276 0.0017550668470847353 -0.09349209111799792" rpy="0 0 0"/>
    <mass value="0.49948793135344544"/>
    <inertia ixx="0.00237" iyy="0.002445" izz="9.8e-05" ixy="6e-06" iyz="-4.8e-05" ixz="0.000207"/>
  </inertial>
  <visual>
    <origin xyz="-0.097619 -0.107944 0.196111" rpy="0 0 0"/>
    <geometry>
      <mesh filename="package://simple_little_white_description/meshes/fl_shin_1.stl" scale="0.001 0.001 0.001"/>
    </geometry>
    <material name="silver"/>
  </visual>
  <collision>
    <origin xyz="0.015 0 -0.07" rpy="0 -0.2 0"/>
    <geometry>
      <box size="0.02 0.03 0.18"/> 
    </geometry>
  </collision>
  <collision>
    <origin xyz="0.01 0 -0.19"/>
    <geometry>
      <sphere radius="0.02"/>
    </geometry>
  </collision>
</link>

<link name="FR_hip">
  <inertial>
    <origin xyz="0.03508927341115779 0.01335892135358984 -0.00010253192976971022" rpy="0 0 0"/>
    <mass value="1.1880376921996947"/>
    <inertia ixx="0.000534" iyy="0.000575" izz="0.000581" ixy="-2.3e-05" iyz="0.0" ixz="0.0"/>
  </inertial>
  <visual>
    <origin xyz="-0.062849 0.051037 0.000872" rpy="0 0 0"/>
    <geometry>
      <mesh filename="package://simple_little_white_description/meshes/fr_hip_1.stl" scale="0.001 0.001 0.001"/>
    </geometry>
    <material name="silver"/>
  </visual>
  <collision>
    <origin xyz="0.0365 0.016 0" rpy="1.57 0 0"/>
    <geometry>
      <cylinder radius="0.031" length="0.055"/>
    </geometry>
  </collision>
</link>

<link name="FR_thigh">
  <inertial>
    <origin xyz="-0.004508553618361166 -0.03057950425042323 -0.03815241663325896" rpy="0 0 0"/>
    <mass value="1.5258674069251719"/>
    <inertia ixx="0.006064" iyy="0.006136" izz="0.000712" ixy="-8.2e-05" iyz="-0.000612" ixz="-0.000488"/>
  </inertial>
  <visual>
    <origin xyz="-0.099349 0.065574 0.000919" rpy="0 0 0"/>
    <geometry>
      <mesh filename="package://simple_little_white_description/meshes/fr_thigh_1.stl" scale="0.001 0.001 0.001"/>
    </geometry>
    <material name="silver"/>
  </visual>
  <collision>
    <origin xyz="0 -0.03 0" rpy="1.57 0 0"/>
    <geometry>
      <cylinder radius="0.031" length="0.055"/>
    </geometry>
  </collision>
  <collision>
    <origin xyz="-0.025 -0.045 -0.08" rpy="0 0 0"/>
    <geometry>
      <box size="0.02 0.03 0.15"/>
    </geometry>
  </collision>
</link>

<link name="FR_calf">
  <inertial>
    <origin xyz="0.013545717576416441 -0.002156812959451457 -0.09348303178635164" rpy="0 0 0"/>
    <mass value="0.49948964066574203"/>
    <inertia ixx="0.00237" iyy="0.002446" izz="9.8e-05" ixy="-5e-06" iyz="3.8e-05" ixz="0.000207"/>
  </inertial>
  <visual>
    <origin xyz="-0.09762 0.108855 0.195646" rpy="0 0 0"/>
    <geometry>
      <mesh filename="package://simple_little_white_description/meshes/fr_shin_1.stl" scale="0.001 0.001 0.001"/>
    </geometry>
    <material name="silver"/>
  </visual>
  <collision>
    <origin xyz="0.015 0 -0.07" rpy="0 -0.2 0"/>
    <geometry>
      <box size="0.02 0.03 0.18"/>
    </geometry>
  </collision>
  <collision>
    <origin xyz="0.01 0 -0.19"/>
    <geometry>
      <sphere radius="0.02"/>
    </geometry>
  </collision>
</link>

<link name="RL_hip">
  <inertial>
    <origin xyz="-0.03508952830635845 -0.013359271051283268 0.00010280923911701697" rpy="0 0 0"/>
    <mass value="1.188037688013764"/>
    <inertia ixx="0.000534" iyy="0.000575" izz="0.000581" ixy="-2.3e-05" iyz="0.0" ixz="0.0"/>
  </inertial>
  <visual>
    <origin xyz="0.182151 -0.050963 0.000565" rpy="0 0 0"/>
    <geometry>
      <mesh filename="package://simple_little_white_description/meshes/rl_hip_1.stl" scale="0.001 0.001 0.001"/>
    </geometry>
    <material name="silver"/>
  </visual>
  <collision>
    <origin xyz="-0.0365 -0.016 0" rpy="1.57 0 0"/>
    <geometry>
      <cylinder radius="0.031" length="0.055"/>
    </geometry>
  </collision>
</link>

<link name="RL_thigh">
  <inertial>
    <origin xyz="-0.004508704943247233 0.03041494357767835 -0.038282923463854784" rpy="0 0 0"/>
    <mass value="1.5258680170230223"/>
    <inertia ixx="0.006064" iyy="0.006141" izz="0.000707" ixy="8e-05" iyz="0.000589" ixz="-0.000489"/>
  </inertial>
  <visual>
    <origin xyz="0.218651 -0.0655 0.000518" rpy="0 0 0"/>
    <geometry>
      <mesh filename="package://simple_little_white_description/meshes/rl_thigh_1.stl" scale="0.001 0.001 0.001"/>
    </geometry>
    <material name="silver"/>
  </visual>
  <collision>
    <origin xyz="0 0.03 0" rpy="1.57 0 0"/>
    <geometry>
      <cylinder radius="0.031" length="0.055"/>
    </geometry>
  </collision>
  <collision>
    <origin xyz="-0.025 0.045 -0.08" rpy="0 0 0"/>
    <geometry>
      <box size="0.02 0.03 0.15"/>
    </geometry>
  </collision>
</link>

<link name="RL_calf">
  <inertial>
    <origin xyz="0.013545457527134291 0.001755066847083625 -0.09349205927708959" rpy="0 0 0"/>
    <mass value="0.49948793135344544"/>
    <inertia ixx="0.00237" iyy="0.002445" izz="9.8e-05" ixy="6e-06" iyz="-4.8e-05" ixz="0.000207"/>
  </inertial>
  <visual>
    <origin xyz="0.22038 -0.107944 0.195428" rpy="0 0 0"/>
    <geometry>
      <mesh filename="package://simple_little_white_description/meshes/rl_shin_1.stl" scale="0.001 0.001 0.001"/>
    </geometry>
    <material name="silver"/>
  </visual>
  <collision>
    <origin xyz="0.015 0 -0.07" rpy="0 -0.2 0"/>
    <geometry>
      <box size="0.02 0.03 0.18"/>
    </geometry>
  </collision>
  <collision>
    <origin xyz="0.01 0 -0.19"/>
    <geometry>
      <sphere radius="0.02"/>
    </geometry>
  </collision>
</link>

<link name="RR_hip">
  <inertial>
    <origin xyz="-0.03508917469303055 0.013358921334036239 4.844106465489432e-05" rpy="0 0 0"/>
    <mass value="1.188037688013764"/>
    <inertia ixx="0.000534" iyy="0.000575" izz="0.000581" ixy="2.3e-05" iyz="-0.0" ixz="-0.0"/>
  </inertial>
  <visual>
    <origin xyz="0.182151 0.051037 0.000346" rpy="0 0 0"/>
    <geometry>
      <mesh filename="package://simple_little_white_description/meshes/rr_hip_1.stl" scale="0.001 0.001 0.001"/>
    </geometry>
    <material name="silver"/>
  </visual>
  <collision>
    <origin xyz="-0.0365 0.016 0" rpy="1.57 0 0"/>
    <geometry>
      <cylinder radius="0.031" length="0.055"/>
    </geometry>
  </collision>
</link>

<link name="RR_thigh">
  <inertial>
    <origin xyz="-0.004508820075855707 -0.03057950425042348 -0.038152384792349586" rpy="0 0 0"/>
    <mass value="1.5258674069251719"/>
    <inertia ixx="0.006064" iyy="0.006136" izz="0.000712" ixy="-8.2e-05" iyz="-0.000612" ixz="-0.000488"/>
  </inertial>
  <visual>
    <origin xyz="0.21865 0.065574 0.000236" rpy="0 0 0"/>
    <geometry>
      <mesh filename="package://simple_little_white_description/meshes/rr_thigh_1.stl" scale="0.001 0.001 0.001"/>
    </geometry>
    <material name="silver"/>
  </visual>
  <collision>
    <origin xyz="0 -0.03 0" rpy="1.57 0 0"/>
    <geometry>
      <cylinder radius="0.031" length="0.055"/>
    </geometry>
  </collision>
  <collision>
    <origin xyz="-0.025 -0.045 -0.08" rpy="0 0 0"/>
    <geometry>
      <box size="0.02 0.03 0.15"/>
    </geometry>
  </collision>
</link>

<link name="RR_calf">
  <inertial>
    <origin xyz="0.013545451118921137 -0.002156812959451526 -0.09348399994544224" rpy="0 0 0"/>
    <mass value="0.49948964066574203"/>
    <inertia ixx="0.00237" iyy="0.002446" izz="9.8e-05" ixy="-5e-06" iyz="3.8e-05" ixz="0.000207"/>
  </inertial>
  <visual>
    <origin xyz="0.220379 0.108855 0.194962" rpy="0 0 0"/>
    <geometry>
      <mesh filename="package://simple_little_white_description/meshes/rr_shin_1.stl" scale="0.001 0.001 0.001"/>
    </geometry>
    <material name="silver"/>
  </visual>
  <collision>
    <origin xyz="0.015 0 -0.07" rpy="0 -0.2 0"/>
    <geometry>
      <box size="0.02 0.03 0.18"/>
    </geometry>
  </collision>
  <collision>
    <origin xyz="0.01 0 -0.19"/>
    <geometry>
      <sphere radius="0.02"/>
    </geometry>
  </collision>
</link>

<joint name="FL_hip_joint" type="revolute">
  <origin xyz="0.0628 0.051 0" rpy="0 0 0"/>
  <parent link="base_link"/>
  <child link="FL_hip"/>
  <axis xyz="1 0 0"/>
  <limit
    lower="-1.0472"
    upper="1.0472"
    effort="23.7"
    velocity="30.1" />
</joint>

<joint name="FL_thigh_joint" type="revolute">
  <origin xyz="0.0365 0.014537 0" rpy="0 0 0"/>
  <parent link="FL_hip"/>
  <child link="FL_thigh"/>
  <axis xyz="0 1 0"/>
  <limit
    lower="-1.5708"
    upper="3.4907"
    effort="23.7"
    velocity="30.1" />
</joint>

<joint name="FL_calf_joint" type="revolute">
  <origin xyz="-0.001729 0.042 -0.194" rpy="0 0 0"/>
  <parent link="FL_thigh"/>
  <child link="FL_calf"/>
  <axis xyz="0 1 0"/>
  <limit
    lower="-2.7227"
    upper="-0.83776"
    effort="45.43"
    velocity="15.70" />
</joint>

<joint name="FR_hip_joint" type="revolute">
  <origin xyz="0.0628 -0.051 0" rpy="0 0 0"/>
  <parent link="base_link"/>
  <child link="FR_hip"/>
  <axis xyz="1 0 0"/>
  <limit
    lower="-1.0472"
    upper="1.0472"
    effort="23.7"
    velocity="30.1" />
</joint>

<joint name="FR_thigh_joint" type="revolute">
  <origin xyz="0.0365 -0.014537 0" rpy="0 0 0"/>
  <parent link="FR_hip"/>
  <child link="FR_thigh"/>
  <axis xyz="0 1 0"/>
  <limit
    lower="-1.5708"
    upper="3.4907"
    effort="23.7"
    velocity="30.1" />
</joint>

<joint name="FR_calf_joint" type="revolute">
  <origin xyz="-0.001729 -0.042 -0.194" rpy="0 0 0"/>
  <parent link="FR_thigh"/>
  <child link="FR_calf"/>
  <axis xyz="0 1 0"/>
  <limit
    lower="-2.7227"
    upper="-0.83776"
    effort="45.43"
    velocity="15.70" />
</joint>

<joint name="RL_hip_joint" type="revolute">
  <origin xyz="-0.182151 0.051 0" rpy="0 0 0"/>
  <parent link="base_link"/>
  <child link="RL_hip"/>
  <axis xyz="1 0 0"/>
  <limit
    lower="-1.0472"
    upper="1.0472"
    effort="23.7"
    velocity="30.1" />
</joint>

<joint name="RL_thigh_joint" type="revolute">
  <origin xyz="-0.0365 0.014537 0" rpy="0 0 0"/>
  <parent link="RL_hip"/>
  <child link="RL_thigh"/>
  <axis xyz="0 1 0"/>
  <limit
    lower="-0.5236"
    upper="4.5379"
    effort="23.7"
    velocity="30.1" />
</joint>

<joint name="RL_calf_joint" type="revolute">
  <origin xyz="-0.001729 0.042 -0.194" rpy="0 0 0"/>
  <parent link="RL_thigh"/>
  <child link="RL_calf"/>
  <axis xyz="0 1 0"/>
  <limit
    lower="-2.7227"
    upper="-0.83776"
    effort="45.43"
    velocity="15.70" />
</joint>

<joint name="RR_hip_joint" type="revolute">
  <origin xyz="-0.182151 -0.051 0" rpy="0 0 0"/>
  <parent link="base_link"/>
  <child link="RR_hip"/>
  <axis xyz="1 0 0"/>
  <limit
    lower="-1.0472"
    upper="1.0472"
    effort="23.7"
    velocity="30.1" />
</joint>

<joint name="RR_thigh_joint" type="revolute">
  <origin xyz="-0.0365 -0.014537 0" rpy="0 0 0"/>
  <parent link="RR_hip"/>
  <child link="RR_thigh"/>
  <axis xyz="0 1 0"/>
  <limit
    lower="-0.5236"
    upper="4.5379"
    effort="23.7"
    velocity="30.1" />
</joint>

<joint name="RR_calf_joint" type="revolute">
  <origin xyz="-0.001729 -0.042 -0.194" rpy="0 0 0"/>
  <parent link="RR_thigh"/>
  <child link="RR_calf"/>
  <axis xyz="0 1 0"/>
  <limit
    lower="-2.7227"
    upper="-0.83776"
    effort="45.43"
    velocity="15.70" />
</joint>

</robot>
