<mujoco model="littlewhite">
  <compiler angle="radian" meshdir="meshes"/>

  <default>
    <default class="little_white">
      <geom friction="0.4" margin="0.001" condim="1"/>
      <joint axis="0 1 0" frictionloss="0.2"/>
      <motor ctrlrange="-23.7 23.7"/>
      <default class="abduction">
        <joint axis="1 0 0" range="-1.0472 1.0472" damping="0.38" armature="0.001"/>
      </default>
      <default class="hip">
        <default class="front_hip">
          <joint range="-1.5708 3.4907" damping="0.29" armature="0.0027"/>
        </default>
        <default class="back_hip">
          <joint range="-0.5236 4.5379" damping="0.29" armature="0.0027"/>
        </default>
      </default>
      <default class="knee">
        <joint range="-1.91 0.0" damping="0.22" armature="0.0058"/>
        <motor ctrlrange="-45.43 45.43"/>
      </default>
      <default class="visual">
        <geom type="mesh" contype="0" conaffinity="0" group="2"/>
      </default>
      <default class="collision">
        <geom group="3"/>
        <default class="foot">
          <geom size="0.022" pos="-0.002 0 -0.213" priority="1" condim="3"
            friction="0.4 0.02 0.01"/>
        </default>
      </default>
    </default>
  </default>
  <asset>
    <mesh name="base_link" file="base_link.STL"/>
    <mesh name="base_link_collision" file="base_link_collision.stl"/>
    <mesh name="FL_hip_link" file="FL_hip_link.STL"/>
    <mesh name="FL_hip_collision" file="FL_hip_collision.stl"/>
    <mesh name="FL_thigh_link" file="FL_thigh_link.STL"/>
    <mesh name="FL_thigh_collision" file="FL_thigh_collision.stl"/>
    <mesh name="FL_calf_link" file="FL_calf_link.STL"/>
    <mesh name="FL_calf_collision" file="FL_calf_collision.stl"/>
    <mesh name="FL_paw_link" file="FL_paw_link.STL"/>
    <mesh name="FL_paw_collision" file="FL_paw_collision.stl"/>
    <mesh name="FR_hip_link" file="FR_hip_link.STL"/>
    <mesh name="FR_hip_collision" file="FR_hip_collision.stl"/>
    <mesh name="FR_thigh_link" file="FR_thigh_link.STL"/>
    <mesh name="FR_thigh_collision" file="FR_thigh_collision.stl"/>
    <mesh name="FR_calf_link" file="FR_calf_link.STL"/>
    <mesh name="FR_calf_collision" file="FR_calf_collision.stl"/>
    <mesh name="FR_paw_link" file="FR_paw_link.STL"/>
    <mesh name="RL_hip_link" file="RL_hip_link.STL"/>
    <mesh name="RL_hip_collision" file="RL_hip_collision.stl"/>
    <mesh name="RL_thigh_link" file="RL_thigh_link.STL"/>
    <mesh name="RL_calf_link" file="RL_calf_link.STL"/>
    <mesh name="RL_paw_link" file="RL_paw_link.STL"/>
    <mesh name="RR_hip_link" file="RR_hip_link.STL"/>
    <mesh name="RR_hip_collision" file="RR_hip_collision.stl"/>
    <mesh name="RR_thigh_link" file="RR_thigh_link.STL"/>
    <mesh name="RR_calf_link" file="RR_calf_link.STL"/>
    <mesh name="RR_paw_link" file="RR_paw_link.STL"/>
  </asset>

  <worldbody>
    <body name="base_link" pos="0 0 0.445" childclass="little_white" >
      <inertial pos="-0.01204342 -0.00011397 -0.00061410" quat="1 0 0 0"
        mass="2.0"
        diaginertia="0.00509927 0.01393531 0.01818843" />
      <freejoint />
      <geom type="mesh" contype="0" conaffinity="0" group="1" density="0" rgba="0.792157 0.819608 0.933333 1" mesh="base_link"/>
      <geom type="mesh" rgba="0.792157 0.819608 0.933333 1" mesh="base_link_collision" class="collision"/>
      <site name="imu" pos="0 0 0" />
      <body name="FL_hip_link" pos="0.1234 0.0510661 0">
        <inertial pos="0.0333133 0.00218418 -3.895e-05" quat="0.502451 0.491407 -0.503372 0.502672" mass="0.3" diaginertia="0.000284894 0.000263419 0.000178087"/>
        <joint name="FL_hip_joint" class="abduction"/>
        <geom type="mesh" contype="0" conaffinity="0" group="1" density="0" rgba="0.792157 0.819608 0.933333 1" mesh="FL_hip_link"/>
        <geom type="mesh" rgba="0.792157 0.819608 0.933333 1" mesh="FL_hip_collision" class="collision"/>
        <body name="FL_thigh_link" pos="0.0365 0.0595339 0">
          <inertial pos="-0.049488 0.00014953 -0.0849763" quat="0.680655 0.155332 0.164482 0.696797" mass="0.48" diaginertia="0.00215888 0.00206806 0.000157681"/>
          <joint name="FL_thigh_joint" class="front_hip"/>
          <geom type="mesh" contype="0" conaffinity="0" group="1" density="0" rgba="0.792157 0.819608 0.933333 1" mesh="FL_thigh_link"/>
          <geom type="mesh" rgba="0.792157 0.819608 0.933333 1" mesh="FL_thigh_collision" class="collision"/>
          <body name="FL_calf_link" pos="-0.079798 0.00571 -0.177735">
            <inertial pos="0.0500631 -0.00396519 -0.0818502" quat="0.699002 -0.169526 -0.165578 0.674716" mass="0.05" diaginertia="0.000209137 0.000203789 8.67142e-06"/>
            <joint name="FL_calf_joint" class="knee"/>
            <geom type="mesh" contype="0" conaffinity="0" group="1" density="0" rgba="0.792157 0.819608 0.933333 1" mesh="FL_calf_link"/>
            <geom type="mesh" rgba="0.792157 0.819608 0.933333 1" mesh="FL_calf_collision" class="collision"/>
            <geom pos="0.0808649 -0.00455 -0.135562" quat="0.707108 0 0 -0.707106" type="mesh" contype="0" conaffinity="0" group="1" density="0" rgba="0.792157 0.819608 0.933333 1" mesh="FL_paw_link"/>
            <geom pos="0.0808649 -0.00455 -0.135562" quat="0.707108 0 0 -0.707106" type="mesh" rgba="0.792157 0.819608 0.933333 1" mesh="FL_paw_collision" class="collision"/>
          </body>
        </body>
      </body>
      <body name="FR_hip_link" pos="0.1234 -0.0509339 0">
        <inertial pos="0.0276363 0.00800779 -7.06e-06" quat="0.420116 0.347689 0.614895 0.569666" mass="0.3" diaginertia="0.000243694 0.000241965 0.000180311"/>
        <joint name="FR_hip_joint" class="abduction"/>
        <geom type="mesh" contype="0" conaffinity="0" group="1" density="0" rgba="0.792157 0.819608 0.933333 1" mesh="FR_hip_link"/>
        <geom type="mesh" rgba="0.792157 0.819608 0.933333 1" mesh="FR_hip_collision" class="collision"/>
        <body name="FR_thigh_link" pos="0.0365 -0.0596661 0">
          <inertial pos="-0.0494894 -0.00014939 -0.0849756" quat="0.696857 0.164457 0.155336 0.680599" mass="0.48" diaginertia="0.00215877 0.002068 0.00015763"/>
          <joint name="FR_thigh_joint" class="front_hip"/>
          <geom type="mesh" contype="0" conaffinity="0" group="1" density="0" rgba="0.792157 0.819608 0.933333 1" mesh="FR_thigh_link"/>
          <geom type="mesh" rgba="0.792157 0.819608 0.933333 1" mesh="FR_thigh_collision" class="collision"/>
          <body name="FR_calf_link" pos="-0.079798 -0.00571 -0.177735">
            <inertial pos="0.0500641 0.00396654 -0.0818502" quat="0.674957 -0.165521 -0.169591 0.698767" mass="0.05" diaginertia="0.000209137 0.000203799 8.67242e-06"/>
            <joint name="FR_calf_joint" class="knee"/>
            <geom type="mesh" contype="0" conaffinity="0" group="1" density="0" rgba="0.792157 0.819608 0.933333 1" mesh="FR_calf_link"/>
            <geom type="mesh" rgba="0.792157 0.819608 0.933333 1" mesh="FR_calf_collision" class="collision"/>
            <geom pos="0.0808737 0.00455 -0.135559" quat="1 0 0 0" type="mesh" contype="0" conaffinity="0" group="1" density="0" rgba="0.792157 0.819608 0.933333 1" mesh="FR_paw_link"/>
            <geom pos="0.0808737 0.00455 -0.135559" quat="1 0 0 0" type="mesh" rgba="0.792157 0.819608 0.933333 1" mesh="FL_paw_collision" class="collision"/>
          </body>
        </body>
      </body>
      <body name="RL_hip_link" pos="-0.1234 0.0510661 0">
        <inertial pos="-0.0334887 0.00218418 -0.00018813" quat="0.489831 0.501572 -0.501905 0.50654" mass="0.3" diaginertia="0.000285202 0.000263427 0.000178392"/>
        <joint name="RL_hip_joint" class="abduction"/>
        <geom type="mesh" contype="0" conaffinity="0" group="1" density="0" rgba="0.792157 0.819608 0.933333 1" mesh="RL_hip_link"/>
        <geom type="mesh" rgba="0.792157 0.819608 0.933333 1" mesh="RL_hip_collision" class="collision"/>
        <body name="RL_thigh_link" pos="-0.0365 0.0595339 0">
          <inertial pos="-0.0519249 0.00014953 -0.0835095" quat="0.678202 0.165396 0.174306 0.69448" mass="0.48" diaginertia="0.00215889 0.00206807 0.000157679"/>
          <joint name="RL_thigh_joint" class="back_hip"/>
          <geom type="mesh" contype="0" conaffinity="0" group="1" density="0" rgba="0.792157 0.819608 0.933333 1" mesh="RL_thigh_link"/>
          <geom type="mesh" rgba="0.792157 0.819608 0.933333 1" mesh="FL_thigh_collision" class="collision"/>
          <body name="RL_calf_link" pos="-0.0845699 0.00571 -0.175356">
            <inertial pos="0.0468304 -0.00396639 -0.0835506" quat="0.702181 -0.158127 -0.154021 0.676916" mass="0.05" diaginertia="0.000209137 0.000204224 8.24673e-06"/>
            <joint name="RL_calf_joint" class="knee"/>
            <geom type="mesh" contype="0" conaffinity="0" group="1" density="0" rgba="0.792157 0.819608 0.933333 1" mesh="RL_calf_link"/>
            <geom type="mesh" rgba="0.792157 0.819608 0.933333 1" mesh="FL_calf_collision" class="collision"/>
            <geom pos="0.0757393 -0.00455 -0.138307" quat="1 0 0 0" type="mesh" contype="0" conaffinity="0" group="1" density="0" rgba="0.792157 0.819608 0.933333 1" mesh="RL_paw_link"/>
            <geom pos="0.0757393 -0.00455 -0.138307" quat="1 0 0 0" type="mesh" rgba="0.792157 0.819608 0.933333 1" mesh="FL_paw_collision" class="collision"/>
          </body>
        </body>
      </body>
      <body name="RR_hip_link" pos="-0.1234 -0.0509339 0">
        <inertial pos="-0.0276716 0.00800779 -3.868e-05" quat="0.596089 0.589502 0.388998 0.381898" mass="0.3" diaginertia="0.000243679 0.00024218 0.00018049"/>
        <joint name="RR_hip_joint" class="abduction"/>
        <geom type="mesh" contype="0" conaffinity="0" group="1" density="0" rgba="0.792157 0.819608 0.933333 1" mesh="RR_hip_link"/>
        <geom type="mesh" rgba="0.792157 0.819608 0.933333 1" mesh="RR_hip_collision" class="collision"/>
        <body name="RR_thigh_link" pos="-0.0365 -0.0596661 0">
          <inertial pos="-0.0519261 -0.00014945 -0.0835081" quat="0.694559 0.174275 0.165407 0.678127" mass="0.48" diaginertia="0.0021588 0.00206804 0.000157622"/>
          <joint name="RR_thigh_joint" class="back_hip"/>
          <geom type="mesh" contype="0" conaffinity="0" group="1" density="0" rgba="0.792157 0.819608 0.933333 1" mesh="RR_thigh_link"/>
          <geom type="mesh" rgba="0.792157 0.819608 0.933333 1" mesh="FR_thigh_collision" class="collision"/>
          <body name="RR_calf_link" pos="-0.0849051 -0.00571 -0.175353">
            <inertial pos="0.0471655 0.00396654 -0.083554" quat="0.676915 -0.154022 -0.158127 0.702182" mass="0.05" diaginertia="0.000209137 0.000204224 8.24662e-06"/>
            <joint name="RR_calf_joint" class="knee"/>
            <geom type="mesh" contype="0" conaffinity="0" group="1" density="0" rgba="0.792157 0.819608 0.933333 1" mesh="RR_calf_link"/>
            <geom type="mesh" rgba="0.792157 0.819608 0.933333 1" mesh="FR_calf_collision" class="collision"/>
            <geom pos="0.0760744 0.00455 -0.13831" quat="1 0 0 0" type="mesh" contype="0" conaffinity="0" group="1" density="0" rgba="0.792157 0.819608 0.933333 1" mesh="RR_paw_link"/>
            <geom pos="0.0760744 0.00455 -0.13831" quat="1 0 0 0" type="mesh" rgba="0.792157 0.819608 0.933333 1" mesh="FL_paw_collision" class="collision"/>
          </body>
        </body>
      </body>
    </body>
  </worldbody>

  <actuator>
    <motor class="abduction" name="FL_hip" joint="FL_hip_joint" />
    <motor class="hip" name="FL_thigh" joint="FL_thigh_joint" />
    <motor class="knee" name="FL_calf" joint="FL_calf_joint" />
    <motor class="abduction" name="FR_hip" joint="FR_hip_joint" />
    <motor class="hip" name="FR_thigh" joint="FR_thigh_joint" />
    <motor class="knee" name="FR_calf" joint="FR_calf_joint" />
    <motor class="abduction" name="RR_hip" joint="RR_hip_joint" />
    <motor class="hip" name="RR_thigh" joint="RR_thigh_joint" />
    <motor class="knee" name="RR_calf" joint="RR_calf_joint" />
    <motor class="abduction" name="RL_hip" joint="RL_hip_joint" />
    <motor class="hip" name="RL_thigh" joint="RL_thigh_joint" />
    <motor class="knee" name="RL_calf" joint="RL_calf_joint" />
  </actuator>

  <sensor>
    <jointpos name="FL_hip_pos" joint="FL_hip_joint" />
    <jointpos name="FL_thigh_pos" joint="FL_thigh_joint" />
    <jointpos name="FL_calf_pos" joint="FL_calf_joint" />
    <jointpos name="FR_hip_pos" joint="FR_hip_joint" />
    <jointpos name="FR_thigh_pos" joint="FR_thigh_joint" />
    <jointpos name="FR_calf_pos" joint="FR_calf_joint" />
    <jointpos name="RR_hip_pos" joint="RR_hip_joint" />
    <jointpos name="RR_thigh_pos" joint="RR_thigh_joint" />
    <jointpos name="RR_calf_pos" joint="RR_calf_joint" />
    <jointpos name="RL_hip_pos" joint="RL_hip_joint" />
    <jointpos name="RL_thigh_pos" joint="RL_thigh_joint" />
    <jointpos name="RL_calf_pos" joint="RL_calf_joint" />

    <jointvel name="FL_hip_vel" joint="FL_hip_joint" />
    <jointvel name="FL_thigh_vel" joint="FL_thigh_joint" />
    <jointvel name="FL_calf_vel" joint="FL_calf_joint" />
    <jointvel name="FR_hip_vel" joint="FR_hip_joint" />
    <jointvel name="FR_thigh_vel" joint="FR_thigh_joint" />
    <jointvel name="FR_calf_vel" joint="FR_calf_joint" />
    <jointvel name="RR_hip_vel" joint="RR_hip_joint" />
    <jointvel name="RR_thigh_vel" joint="RR_thigh_joint" />
    <jointvel name="RR_calf_vel" joint="RR_calf_joint" />
    <jointvel name="RL_hip_vel" joint="RL_hip_joint" />
    <jointvel name="RL_thigh_vel" joint="RL_thigh_joint" />
    <jointvel name="RL_calf_vel" joint="RL_calf_joint" />

    <jointactuatorfrc name="FL_hip_torque" joint="FL_hip_joint" noise="0.01" />
    <jointactuatorfrc name="FL_thigh_torque" joint="FL_thigh_joint" noise="0.01" />
    <jointactuatorfrc name="FL_calf_torque" joint="FL_calf_joint" noise="0.01" />
    <jointactuatorfrc name="FR_hip_torque" joint="FR_hip_joint" noise="0.01" />
    <jointactuatorfrc name="FR_thigh_torque" joint="FR_thigh_joint" noise="0.01" />
    <jointactuatorfrc name="FR_calf_torque" joint="FR_calf_joint" noise="0.01" />
    <jointactuatorfrc name="RR_hip_torque" joint="RR_hip_joint" noise="0.01" />
    <jointactuatorfrc name="RR_thigh_torque" joint="RR_thigh_joint" noise="0.01" />
    <jointactuatorfrc name="RR_calf_torque" joint="RR_calf_joint" noise="0.01" />
    <jointactuatorfrc name="RL_hip_torque" joint="RL_hip_joint" noise="0.01" />
    <jointactuatorfrc name="RL_thigh_torque" joint="RL_thigh_joint" noise="0.01" />
    <jointactuatorfrc name="RL_calf_torque" joint="RL_calf_joint" noise="0.01" />

    <framequat name="imu_quat" objtype="site" objname="imu" />
    <gyro name="imu_gyro" site="imu" />
    <accelerometer name="imu_acc" site="imu" />
    
    <framepos name="frame_pos" objtype="site" objname="imu" />
    <framelinvel name="frame_vel" objtype="site" objname="imu" />
  </sensor>

</mujoco>
